Workbook

Sheet Project Plan
A1: ECS FEDERAL — 18-WEEK OOTB SERVICENOW BASELINE PROJECT PLAN
A2: SH-PP-01 · Shared — ECS Team + Customer · Template: update Project Start Date (B3) to generate all dates
A3: Project Start Date: | B3: 45901 | C3: ← Change this date; all task dates recalculate automatically
A4: LEGEND: Phase Header (dark navy) | Task Row (white/alt) | ✦ Milestone (gold) | Recurring Governance (teal) | Predecessors = Task IDs in column A
A6: ID | B6: WBS | C6: Phase | D6: Sprint | E6: Task Name | F6: Duration (Days) | G6: Start Date | H6: Finish Date | I6: Predecessors | J6: ECS Primary | K6: ECS Support | L6: Customer Primary | M6: Customer Support | N6: Status | O6: % Complete | P6: Notes / Deliverables
A7: 1 | B7: 0 | C7: Sprint 0 | D7: Sprint 0 | E7: SPRINT 0 — ENGAGEMENT SETUP | F7: 10 | G7: =WORKDAY($B$3,0) -> 45901 | H7: =WORKDAY(G7,9) -> 45912 | J7: EM | K7: SA, PC | L7: Sponsor, CustPM | N7: Not Started | O7: 0 | P7: Weeks 1–2. All setup activities to ensure team and environment are ready for Sprint 1.
A8: 2 | B8: 0.1 | C8: Sprint 0 | D8: Sprint 0 | E8: Internal ECS kickoff — SOW review & consultant assignment | F8: 1 | G8: =WORKDAY($B$3,0) -> 45901 | H8: =WORKDAY(G8,0) -> 45901 | J8: EM | K8: PM | N8: Not Started | O8: 0 | P8: Review SOW scope, confirm consultant roles, load sprint tooling and templates.
A9: 3 | B9: 0.2 | C9: Sprint 0 | D9: Sprint 0 | E9: Contract & SOW finalization (customer signature) | F9: 1 | G9: =WORKDAY($B$3,0) -> 45901 | H9: =WORKDAY(G9,0) -> 45901 | J9: EM | L9: Sponsor | M9: CustPM | N9: Not Started | O9: 0 | P9: Confirm signed SOW before Sprint 1 commitment.
A10: 4 | B10: 0.3 | C10: Sprint 0 | D10: Sprint 0 | E10: Customer kickoff meeting | F10: 1 | G10: =WORKDAY($B$3,1) -> 45902 | H10: =WORKDAY(G10,0) -> 45902 | I10: 2,3 | J10: EM, SA | K10: PC | L10: Sponsor, CustPM | M10: TechLead | N10: Not Started | O10: 0 | P10: Introductions, engagement overview, 18-week journey walk-through, Q&A.
A11: 5 | B11: 0.4 | C11: Sprint 0 | D11: Sprint 0 | E11: Environment provisioning — dev / test / prod instances | F11: 3 | G11: =WORKDAY($B$3,1) -> 45902 | H11: =WORKDAY(G11,2) -> 45904 | I11: 4 | J11: SA, TC | L11: TechLead | N11: Not Started | O11: 0 | P11: ServiceNow instance request, MID server setup, network access.
A12: 6 | B12: 0.5 | C12: Sprint 0 | D12: Sprint 0 | E12: Access & credentials setup (admin, consultant, test accounts) | F12: 2 | G12: =WORKDAY($B$3,1) -> 45902 | H12: =WORKDAY(G12,1) -> 45903 | I12: 4 | J12: TC | K12: SA | L12: TechLead | N12: Not Started | O12: 0 | P12: ECS consultant accounts, customer admin accounts, SSO config baseline.
A13: 7 | B13: 0.6 | C13: Sprint 0 | D13: Sprint 0 | E13: Governance & decision rights workshop | F13: 1 | G13: =WORKDAY($B$3,2) -> 45903 | H13: =WORKDAY(G13,0) -> 45903 | I13: 4 | J13: EM, PC | L13: Sponsor, CustPM | M13: TechLead | N13: Not Started | O13: 0 | P13: Establish customization council, RACI, escalation path, decision log.
A14: 8 | B14: 0.7 | C14: Sprint 0 | D14: Sprint 0 | E14: Customization Council charter signed | F14: 1 | G14: =WORKDAY($B$3,3) -> 45904 | H14: =WORKDAY(G14,0) -> 45904 | I14: 7 | J14: EM | L14: Sponsor | N14: Not Started | O14: 0 | P14: Council charter defines quorum, meeting cadence, and veto rights for any scope deviation.
A15: 9 | B15: 0.8 | C15: Sprint 0 | D15: Sprint 0 | E15: Communication plan & cadence established | F15: 1 | G15: =WORKDAY($B$3,2) -> 45903 | H15: =WORKDAY(G15,0) -> 45903 | I15: 4 | J15: EM | L15: CustPM | N15: Not Started | O15: 0 | P15: Weekly status report schedule, bi-weekly sponsor sync, sprint demo invites.
A16: 10 | B16: 0.9 | C16: Sprint 0 | D16: Sprint 0 | E16: Risk register initialized | F16: 1 | G16: =WORKDAY($B$3,3) -> 45904 | H16: =WORKDAY(G16,0) -> 45904 | I16: 4 | J16: EM, PC | L16: CustPM | N16: Not Started | O16: 0 | P16: Populate with known risks: data readiness, SME availability, environment delays.
A17: 11 | B17: 0.10 | C17: Sprint 0 | D17: Sprint 0 | E17: Foundation Data Pack distributed to customer | F17: 1 | G17: =WORKDAY($B$3,4) -> 45905 | H17: =WORKDAY(G17,0) -> 45905 | I17: 4 | J17: PC | L17: CustPM | M17: SME-ITSM | N17: Not Started | O17: 0 | P17: AP-01 workbooks: users, locations, departments, groups, assignment rules, SLAs, schedules.
A18: 12 | B18: 0.11 | C18: Sprint 0 | D18: Sprint 0 | E18: Stakeholder mapping completed | F18: 1 | G18: =WORKDAY($B$3,4) -> 45905 | H18: =WORKDAY(G18,0) -> 45905 | I18: 4 | J18: EM | L18: CustPM | M18: Sponsor | N18: Not Started | O18: 0 | P18: Identify all SMEs, decision owners, and change champions per process area.
A19: 13 | B19: 0.12 | C19: Sprint 0 | D19: Sprint 0 | E19: Sprint 0 readiness validation (ECS checklist) | F19: 1 | G19: =WORKDAY($B$3,9) -> 45912 | H19: =WORKDAY(G19,0) -> 45912 | I19: 5,6,7,8,9,10,11,12 | J19: EM | K19: SA | L19: CustPM | N19: Not Started | O19: 0 | P19: Confirm: env provisioned, access live, governance signed, data pack distributed, risks logged.
A20: 14 | B20: 0.M | C20: Sprint 0 | D20: Sprint 0 | E20: ✦ MILESTONE: Sprint 0 Complete — Ready to Build | F20: — | G20: =WORKDAY($B$3,9) -> 45912 | H20: =G20 -> 45912 | I20: 13 | N20: Not Started | O20: 0
A21: 15 | B21: 1 | C21: Month 1 | D21: Sprint 1 | E21: SPRINT 1 — PLATFORM FOUNDATION & ITSM DESIGN | F21: 10 | G21: =WORKDAY($B$3,10) -> 45915 | H21: =WORKDAY(G21,9) -> 45926 | J21: SA, PC | K21: EM | L21: CustPM, TechLead | M21: SME-ITSM | N21: Not Started | O21: 0 | P21: Weeks 3–4. Platform stand-up, CSDM, and ITSM design workshops.
A22: 16 | B22: 1.1 | C22: Month 1 | D22: Sprint 1 | E22: Sprint 1 planning session | F22: 1 | G22: =WORKDAY($B$3,10) -> 45915 | H22: =WORKDAY(G22,0) -> 45915 | I22: 14 | J22: EM, SA | K22: PC, TC | L22: CustPM | N22: Not Started | O22: 0 | P22: Story review, sprint backlog confirmation, acceptance criteria.
A23: 17 | B23: 1.2 | C23: Month 1 | D23: Sprint 1 | E23: Platform architecture stand-up & baseline configuration | F23: 3 | G23: =WORKDAY($B$3,10) -> 45915 | H23: =WORKDAY(G23,2) -> 45917 | I23: 16,5 | J23: SA, TC | L23: TechLead | N23: Not Started | O23: 0 | P23: CMDB scope settings, update sets, source control, MID server validation.
A24: 18 | B24: 1.3 | C24: Month 1 | D24: Sprint 1 | E24: CSDM definition workshop | F24: 2 | G24: =WORKDAY($B$3,10) -> 45915 | H24: =WORKDAY(G24,1) -> 45916 | I24: 16 | J24: SA, PC | L24: CustPM, TechLead | M24: SME-ITSM | N24: Not Started | O24: 0 | P24: Map customer services, apps, and CIs to CSDM layers. Define service taxonomy.
A25: 19 | B25: 1.4 | C25: Month 1 | D25: Sprint 1 | E25: CSDM validation against ServiceNow data model | F25: 2 | G25: =WORKDAY($B$3,12) -> 45917 | H25: =WORKDAY(G25,1) -> 45918 | I25: 18 | J25: SA | K25: TC | L25: TechLead | N25: Not Started | O25: 0 | P25: Validate service-CI relationships; confirm Business Service and Technical Service scope.
A26: 20 | B26: 1.5 | C26: Month 1 | D26: Sprint 1 | E26: ITSM design workshop — Incident Management | F26: 1 | G26: =WORKDAY($B$3,10) -> 45915 | H26: =WORKDAY(G26,0) -> 45915 | I26: 16 | J26: PC | K26: SA | L26: SME-ITSM | M26: CustPM | N26: Not Started | O26: 0 | P26: State model, categorization, priority matrix, routing logic, SLA tiers.
A27: 21 | B27: 1.6 | C27: Month 1 | D27: Sprint 1 | E27: ITSM design workshop — Problem Management | F27: 1 | G27: =WORKDAY($B$3,11) -> 45916 | H27: =WORKDAY(G27,0) -> 45916 | I27: 20 | J27: PC | K27: SA | L27: SME-ITSM | N27: Not Started | O27: 0 | P27: Problem identification triggers, investigation workflow, known error base.
A28: 22 | B28: 1.7 | C28: Month 1 | D28: Sprint 1 | E28: ITSM design workshop — Request Management | F28: 1 | G28: =WORKDAY($B$3,12) -> 45917 | H28: =WORKDAY(G28,0) -> 45917 | I28: 21 | J28: PC | K28: SA | L28: SME-ITSM | M28: SME-Catalog | N28: Not Started | O28: 0 | P28: Request types, fulfillment model, approval tiers, SLA targets.
A29: 23 | B29: 1.8 | C29: Month 1 | D29: Sprint 1 | E29: Foundation Data Pack review — users, groups, locations | F29: 2 | G29: =WORKDAY($B$3,13) -> 45918 | H29: =WORKDAY(G29,1) -> 45919 | I29: 11 | J29: PC | K29: TC | L29: SME-ITSM | M29: TechLead | N29: Not Started | O29: 0 | P29: Review customer-returned workbooks; identify gaps before Sprint 3 config.
A30: 24 | B30: 1.9 | C30: Month 1 | D30: Sprint 1 | E30: Assignment rules & SLA design review | F30: 1 | G30: =WORKDAY($B$3,14) -> 45919 | H30: =WORKDAY(G30,0) -> 45919 | I30: 23 | J30: PC | K30: SA | L30: SME-ITSM | N30: Not Started | O30: 0 | P30: Confirm assignment group structure, SLA definitions, and escalation schedules.
A31: 25 | B31: 1.10 | C31: Month 1 | D31: Sprint 1 | E31: Sprint 1 demo | F31: 1 | G31: =WORKDAY($B$3,18) -> 45925 | H31: =WORKDAY(G31,0) -> 45925 | I31: 17,19,24 | J31: SA, PC | K31: EM | L31: Sponsor, CustPM | M31: TechLead, SME-ITSM | N31: Not Started | O31: 0 | P31: Demo: platform baseline, CSDM service map, design decision recap.
A32: 26 | B32: 1.11 | C32: Month 1 | D32: Sprint 1 | E32: Sprint 1 retro | F32: 1 | G32: =WORKDAY($B$3,19) -> 45926 | H32: =WORKDAY(G32,0) -> 45926 | I32: 25 | J32: EM | K32: SA, PC | L32: CustPM | N32: Not Started | O32: 0 | P32: Velocity, blockers, action items. Update risk register.
A33: 27 | B33: 1.M | C33: Month 1 | D33: Sprint 1 | E33: ✦ MILESTONE: Sprint 1 Complete | F33: — | G33: =WORKDAY($B$3,19) -> 45926 | H33: =G33 -> 45926 | I33: 26 | N33: Not Started | O33: 0
A34: 28 | B34: 2 | C34: Month 1 | D34: Sprint 2 | E34: SPRINT 2 — DISCOVERY & CMDB FOUNDATION | F34: 10 | G34: =WORKDAY($B$3,20) -> 45929 | H34: =WORKDAY(G34,9) -> 45940 | J34: SA, TC | K34: PC | L34: TechLead | M34: SME-ITSM | N34: Not Started | O34: 0 | P34: Weeks 5–6. Discovery tooling, Service Graph Connectors, CMDB normalization, catalog scope.
A35: 29 | B35: 2.1 | C35: Month 1 | D35: Sprint 2 | E35: Sprint 2 planning session | F35: 1 | G35: =WORKDAY($B$3,20) -> 45929 | H35: =WORKDAY(G35,0) -> 45929 | I35: 27 | J35: EM, SA | K35: PC, TC | L35: CustPM | N35: Not Started | O35: 0
A36: 30 | B36: 2.2 | C36: Month 1 | D36: Sprint 2 | E36: Discovery tool installation & network scan configuration | F36: 3 | G36: =WORKDAY($B$3,20) -> 45929 | H36: =WORKDAY(G36,2) -> 45931 | I36: 29 | J36: TC | K36: SA | L36: TechLead | N36: Not Started | O36: 0 | P36: Discovery schedules, credentials, network range scoping.
A37: 31 | B37: 2.3 | C37: Month 1 | D37: Sprint 2 | E37: Service Graph Connectors — SCCM / Intune porting | F37: 4 | G37: =WORKDAY($B$3,20) -> 45929 | H37: =WORKDAY(G37,3) -> 45932 | I37: 29 | J37: TC | K37: SA | L37: TechLead | N37: Not Started | O37: 0 | P37: Port connectors from prior system; validate CI population in CMDB.
A38: 32 | B38: 2.4 | C38: Month 1 | D38: Sprint 2 | E38: CMDB normalization — scope & approach workshop | F38: 1 | G38: =WORKDAY($B$3,20) -> 45929 | H38: =WORKDAY(G38,0) -> 45929 | I38: 29 | J38: SA, PC | L38: TechLead | M38: CustPM | N38: Not Started | O38: 0 | P38: Agree CI classes in scope, normalization rules, rogue CI cleanup approach.
A39: 33 | B39: 2.5 | C39: Month 1 | D39: Sprint 2 | E39: CI class selection workshop | F39: 1 | G39: =WORKDAY($B$3,21) -> 45930 | H39: =WORKDAY(G39,0) -> 45930 | I39: 32,19 | J39: SA | K39: PC | L39: TechLead | M39: SME-ITSM | N39: Not Started | O39: 0 | P39: Select Server, Network, Application CI classes; confirm relationship types.
A40: 34 | B40: 2.6 | C40: Month 1 | D40: Sprint 2 | E40: Initial CMDB data load & relationship validation | F40: 3 | G40: =WORKDAY($B$3,22) -> 45931 | H40: =WORKDAY(G40,2) -> 45933 | I40: 33 | J40: TC | K40: SA | L40: TechLead | N40: Not Started | O40: 0 | P40: Load SCCM/Intune data; validate CI counts, duplicates, relationship integrity.
A41: 35 | B41: 2.7 | C41: Month 1 | D41: Sprint 2 | E41: Service catalog — category structure design workshop | F41: 1 | G41: =WORKDAY($B$3,20) -> 45929 | H41: =WORKDAY(G41,0) -> 45929 | I41: 29 | J41: PC | K41: SA | L41: SME-Catalog | M41: CustPM | N41: Not Started | O41: 0 | P41: Rationalize legacy categories; target ≤15 top-level categories OOTB.
...

Sheet MS Project Import
A1: MS PROJECT IMPORT SHEET — Save this sheet as CSV (comma-delimited) or use File > Import in MS Project. Map columns by header name. Set Start Date on 'Project Plan' sheet tab first.
A2: ID | B2: Outline Level | C2: Name | D2: Duration | E2: Start | F2: Finish | G2: Predecessors | H2: Resource Names | I2: Notes
A3: 1 | B3: 1 | C3: SPRINT 0 — ENGAGEMENT SETUP | D3: 10 days | E3: =WORKDAY('Project Plan'!$B$3,0) -> 45901 | F3: =WORKDAY(E3,9) -> 45912 | H3: EM; SA, PC; Sponsor, CustPM | I3: Weeks 1–2. All setup activities to ensure team and environment are ready for Sprint 1.
A4: 2 | B4: 2 | C4: Internal ECS kickoff — SOW review & consultant assignment | D4: 1 days | E4: =WORKDAY('Project Plan'!$B$3,0) -> 45901 | F4: =WORKDAY(E4,0) -> 45901 | H4: EM; PM | I4: Review SOW scope, confirm consultant roles, load sprint tooling and templates.
A5: 3 | B5: 2 | C5: Contract & SOW finalization (customer signature) | D5: 1 days | E5: =WORKDAY('Project Plan'!$B$3,0) -> 45901 | F5: =WORKDAY(E5,0) -> 45901 | H5: EM; Sponsor; CustPM | I5: Confirm signed SOW before Sprint 1 commitment.
A6: 4 | B6: 2 | C6: Customer kickoff meeting | D6: 1 days | E6: =WORKDAY('Project Plan'!$B$3,1) -> 45902 | F6: =WORKDAY(E6,0) -> 45902 | G6: 2,3 | H6: EM, SA; PC; Sponsor, CustPM; TechLead | I6: Introductions, engagement overview, 18-week journey walk-through, Q&A.
A7: 5 | B7: 2 | C7: Environment provisioning — dev / test / prod instances | D7: 3 days | E7: =WORKDAY('Project Plan'!$B$3,1) -> 45902 | F7: =WORKDAY(E7,2) -> 45904 | G7: 4 | H7: SA, TC; TechLead | I7: ServiceNow instance request, MID server setup, network access.
A8: 6 | B8: 2 | C8: Access & credentials setup (admin, consultant, test accounts) | D8: 2 days | E8: =WORKDAY('Project Plan'!$B$3,1) -> 45902 | F8: =WORKDAY(E8,1) -> 45903 | G8: 4 | H8: TC; SA; TechLead | I8: ECS consultant accounts, customer admin accounts, SSO config baseline.
A9: 7 | B9: 2 | C9: Governance & decision rights workshop | D9: 1 days | E9: =WORKDAY('Project Plan'!$B$3,2) -> 45903 | F9: =WORKDAY(E9,0) -> 45903 | G9: 4 | H9: EM, PC; Sponsor, CustPM; TechLead | I9: Establish customization council, RACI, escalation path, decision log.
A10: 8 | B10: 2 | C10: Customization Council charter signed | D10: 1 days | E10: =WORKDAY('Project Plan'!$B$3,3) -> 45904 | F10: =WORKDAY(E10,0) -> 45904 | G10: 7 | H10: EM; Sponsor | I10: Council charter defines quorum, meeting cadence, and veto rights for any scope deviation.
A11: 9 | B11: 2 | C11: Communication plan & cadence established | D11: 1 days | E11: =WORKDAY('Project Plan'!$B$3,2) -> 45903 | F11: =WORKDAY(E11,0) -> 45903 | G11: 4 | H11: EM; CustPM | I11: Weekly status report schedule, bi-weekly sponsor sync, sprint demo invites.
A12: 10 | B12: 2 | C12: Risk register initialized | D12: 1 days | E12: =WORKDAY('Project Plan'!$B$3,3) -> 45904 | F12: =WORKDAY(E12,0) -> 45904 | G12: 4 | H12: EM, PC; CustPM | I12: Populate with known risks: data readiness, SME availability, environment delays.
A13: 11 | B13: 2 | C13: Foundation Data Pack distributed to customer | D13: 1 days | E13: =WORKDAY('Project Plan'!$B$3,4) -> 45905 | F13: =WORKDAY(E13,0) -> 45905 | G13: 4 | H13: PC; CustPM; SME-ITSM | I13: AP-01 workbooks: users, locations, departments, groups, assignment rules, SLAs, schedules.
A14: 12 | B14: 2 | C14: Stakeholder mapping completed | D14: 1 days | E14: =WORKDAY('Project Plan'!$B$3,4) -> 45905 | F14: =WORKDAY(E14,0) -> 45905 | G14: 4 | H14: EM; CustPM; Sponsor | I14: Identify all SMEs, decision owners, and change champions per process area.
A15: 13 | B15: 2 | C15: Sprint 0 readiness validation (ECS checklist) | D15: 1 days | E15: =WORKDAY('Project Plan'!$B$3,9) -> 45912 | F15: =WORKDAY(E15,0) -> 45912 | G15: 5,6,7,8,9,10,11,12 | H15: EM; SA; CustPM | I15: Confirm: env provisioned, access live, governance signed, data pack distributed, risks logged.
A16: 14 | B16: 0 | C16: ✦ MILESTONE: Sprint 0 Complete — Ready to Build | D16: 0 days | E16: =WORKDAY('Project Plan'!$B$3,9) -> 45912 | F16: =WORKDAY(E16,0) -> 45912 | G16: 13
A17: 15 | B17: 1 | C17: SPRINT 1 — PLATFORM FOUNDATION & ITSM DESIGN | D17: 10 days | E17: =WORKDAY('Project Plan'!$B$3,10) -> 45915 | F17: =WORKDAY(E17,9) -> 45926 | H17: SA, PC; EM; CustPM, TechLead; SME-ITSM | I17: Weeks 3–4. Platform stand-up, CSDM, and ITSM design workshops.
A18: 16 | B18: 2 | C18: Sprint 1 planning session | D18: 1 days | E18: =WORKDAY('Project Plan'!$B$3,10) -> 45915 | F18: =WORKDAY(E18,0) -> 45915 | G18: 14 | H18: EM, SA; PC, TC; CustPM | I18: Story review, sprint backlog confirmation, acceptance criteria.
A19: 17 | B19: 2 | C19: Platform architecture stand-up & baseline configuration | D19: 3 days | E19: =WORKDAY('Project Plan'!$B$3,10) -> 45915 | F19: =WORKDAY(E19,2) -> 45917 | G19: 16,5 | H19: SA, TC; TechLead | I19: CMDB scope settings, update sets, source control, MID server validation.
A20: 18 | B20: 2 | C20: CSDM definition workshop | D20: 2 days | E20: =WORKDAY('Project Plan'!$B$3,10) -> 45915 | F20: =WORKDAY(E20,1) -> 45916 | G20: 16 | H20: SA, PC; CustPM, TechLead; SME-ITSM | I20: Map customer services, apps, and CIs to CSDM layers. Define service taxonomy.
A21: 19 | B21: 2 | C21: CSDM validation against ServiceNow data model | D21: 2 days | E21: =WORKDAY('Project Plan'!$B$3,12) -> 45917 | F21: =WORKDAY(E21,1) -> 45918 | G21: 18 | H21: SA; TC; TechLead | I21: Validate service-CI relationships; confirm Business Service and Technical Service scope.
A22: 20 | B22: 2 | C22: ITSM design workshop — Incident Management | D22: 1 days | E22: =WORKDAY('Project Plan'!$B$3,10) -> 45915 | F22: =WORKDAY(E22,0) -> 45915 | G22: 16 | H22: PC; SA; SME-ITSM; CustPM | I22: State model, categorization, priority matrix, routing logic, SLA tiers.
A23: 21 | B23: 2 | C23: ITSM design workshop — Problem Management | D23: 1 days | E23: =WORKDAY('Project Plan'!$B$3,11) -> 45916 | F23: =WORKDAY(E23,0) -> 45916 | G23: 20 | H23: PC; SA; SME-ITSM | I23: Problem identification triggers, investigation workflow, known error base.
A24: 22 | B24: 2 | C24: ITSM design workshop — Request Management | D24: 1 days | E24: =WORKDAY('Project Plan'!$B$3,12) -> 45917 | F24: =WORKDAY(E24,0) -> 45917 | G24: 21 | H24: PC; SA; SME-ITSM; SME-Catalog | I24: Request types, fulfillment model, approval tiers, SLA targets.
A25: 23 | B25: 2 | C25: Foundation Data Pack review — users, groups, locations | D25: 2 days | E25: =WORKDAY('Project Plan'!$B$3,13) -> 45918 | F25: =WORKDAY(E25,1) -> 45919 | G25: 11 | H25: PC; TC; SME-ITSM; TechLead | I25: Review customer-returned workbooks; identify gaps before Sprint 3 config.
A26: 24 | B26: 2 | C26: Assignment rules & SLA design review | D26: 1 days | E26: =WORKDAY('Project Plan'!$B$3,14) -> 45919 | F26: =WORKDAY(E26,0) -> 45919 | G26: 23 | H26: PC; SA; SME-ITSM | I26: Confirm assignment group structure, SLA definitions, and escalation schedules.
A27: 25 | B27: 2 | C27: Sprint 1 demo | D27: 1 days | E27: =WORKDAY('Project Plan'!$B$3,18) -> 45925 | F27: =WORKDAY(E27,0) -> 45925 | G27: 17,19,24 | H27: SA, PC; EM; Sponsor, CustPM; TechLead, SME-ITSM | I27: Demo: platform baseline, CSDM service map, design decision recap.
A28: 26 | B28: 2 | C28: Sprint 1 retro | D28: 1 days | E28: =WORKDAY('Project Plan'!$B$3,19) -> 45926 | F28: =WORKDAY(E28,0) -> 45926 | G28: 25 | H28: EM; SA, PC; CustPM | I28: Velocity, blockers, action items. Update risk register.
A29: 27 | B29: 0 | C29: ✦ MILESTONE: Sprint 1 Complete | D29: 0 days | E29: =WORKDAY('Project Plan'!$B$3,19) -> 45926 | F29: =WORKDAY(E29,0) -> 45926 | G29: 26
A30: 28 | B30: 1 | C30: SPRINT 2 — DISCOVERY & CMDB FOUNDATION | D30: 10 days | E30: =WORKDAY('Project Plan'!$B$3,20) -> 45929 | F30: =WORKDAY(E30,9) -> 45940 | H30: SA, TC; PC; TechLead; SME-ITSM | I30: Weeks 5–6. Discovery tooling, Service Graph Connectors, CMDB normalization, catalog scope.
A31: 29 | B31: 2 | C31: Sprint 2 planning session | D31: 1 days | E31: =WORKDAY('Project Plan'!$B$3,20) -> 45929 | F31: =WORKDAY(E31,0) -> 45929 | G31: 27 | H31: EM, SA; PC, TC; CustPM
A32: 30 | B32: 2 | C32: Discovery tool installation & network scan configuration | D32: 3 days | E32: =WORKDAY('Project Plan'!$B$3,20) -> 45929 | F32: =WORKDAY(E32,2) -> 45931 | G32: 29 | H32: TC; SA; TechLead | I32: Discovery schedules, credentials, network range scoping.
A33: 31 | B33: 2 | C33: Service Graph Connectors — SCCM / Intune porting | D33: 4 days | E33: =WORKDAY('Project Plan'!$B$3,20) -> 45929 | F33: =WORKDAY(E33,3) -> 45932 | G33: 29 | H33: TC; SA; TechLead | I33: Port connectors from prior system; validate CI population in CMDB.
A34: 32 | B34: 2 | C34: CMDB normalization — scope & approach workshop | D34: 1 days | E34: =WORKDAY('Project Plan'!$B$3,20) -> 45929 | F34: =WORKDAY(E34,0) -> 45929 | G34: 29 | H34: SA, PC; TechLead; CustPM | I34: Agree CI classes in scope, normalization rules, rogue CI cleanup approach.
A35: 33 | B35: 2 | C35: CI class selection workshop | D35: 1 days | E35: =WORKDAY('Project Plan'!$B$3,21) -> 45930 | F35: =WORKDAY(E35,0) -> 45930 | G35: 32,19 | H35: SA; PC; TechLead; SME-ITSM | I35: Select Server, Network, Application CI classes; confirm relationship types.
A36: 34 | B36: 2 | C36: Initial CMDB data load & relationship validation | D36: 3 days | E36: =WORKDAY('Project Plan'!$B$3,22) -> 45931 | F36: =WORKDAY(E36,2) -> 45933 | G36: 33 | H36: TC; SA; TechLead | I36: Load SCCM/Intune data; validate CI counts, duplicates, relationship integrity.
A37: 35 | B37: 2 | C37: Service catalog — category structure design workshop | D37: 1 days | E37: =WORKDAY('Project Plan'!$B$3,20) -> 45929 | F37: =WORKDAY(E37,0) -> 45929 | G37: 29 | H37: PC; SA; SME-Catalog; CustPM | I37: Rationalize legacy categories; target ≤15 top-level categories OOTB.
A38: 36 | B38: 2 | C38: Service catalog — item inventory & prioritization | D38: 2 days | E38: =WORKDAY('Project Plan'!$B$3,21) -> 45930 | F38: =WORKDAY(E38,1) -> 45931 | G38: 35 | H38: PC; SME-Catalog | I38: Inventory existing items; prioritize 13–15 for Sprint 4/6 build.
A39: 37 | B39: 2 | C39: Sprint 2 demo | D39: 1 days | E39: =WORKDAY('Project Plan'!$B$3,28) -> 45939 | F39: =WORKDAY(E39,0) -> 45939 | G39: 30,31,34,36 | H39: SA, TC; EM; Sponsor, CustPM; TechLead | I39: Demo: Discovery scan, CMDB CIs, Service Graph connector results, catalog scope.
A40: 38 | B40: 2 | C40: Sprint 2 retro | D40: 1 days | E40: =WORKDAY('Project Plan'!$B$3,29) -> 45940 | F40: =WORKDAY(E40,0) -> 45940 | G40: 37 | H40: EM; SA, PC; CustPM
...

Sheet SNow PPM Import
A1: SNow PPM IMPORT SHEET — Fields map to ServiceNow Project Task table (pm_project_task). Import via: Project > Import Tasks > Excel/CSV. Dates pull from 'Project Plan' tab.
A2: task_number | B2: short_description | C2: parent_task | D2: phase | E2: planned_start_date | F2: planned_end_date | G2: duration_days | H2: state | I2: assigned_to_role | J2: description | K2: predecessors
A3: ECS-001 | B3: SPRINT 0 — ENGAGEMENT SETUP | D3: Sprint 0 | E3: =WORKDAY('Project Plan'!$B$3,0) -> 45901 | F3: =WORKDAY(E3,9) -> 45912 | G3: 10 | H3: Open | I3: EM; Sponsor, CustPM | J3: Weeks 1–2. All setup activities to ensure team and environment are ready for Sprint 1.
A4: ECS-002 | B4: Internal ECS kickoff — SOW review & consultant assignment | C4: ECS-001 | D4: Sprint 0 | E4: =WORKDAY('Project Plan'!$B$3,0) -> 45901 | F4: =WORKDAY(E4,0) -> 45901 | G4: 1 | H4: Open | I4: EM | J4: Review SOW scope, confirm consultant roles, load sprint tooling and templates.
A5: ECS-003 | B5: Contract & SOW finalization (customer signature) | C5: ECS-001 | D5: Sprint 0 | E5: =WORKDAY('Project Plan'!$B$3,0) -> 45901 | F5: =WORKDAY(E5,0) -> 45901 | G5: 1 | H5: Open | I5: EM; Sponsor | J5: Confirm signed SOW before Sprint 1 commitment.
A6: ECS-004 | B6: Customer kickoff meeting | C6: ECS-001 | D6: Sprint 0 | E6: =WORKDAY('Project Plan'!$B$3,1) -> 45902 | F6: =WORKDAY(E6,0) -> 45902 | G6: 1 | H6: Open | I6: EM, SA; Sponsor, CustPM | J6: Introductions, engagement overview, 18-week journey walk-through, Q&A. | K6: 2,3
A7: ECS-005 | B7: Environment provisioning — dev / test / prod instances | C7: ECS-001 | D7: Sprint 0 | E7: =WORKDAY('Project Plan'!$B$3,1) -> 45902 | F7: =WORKDAY(E7,2) -> 45904 | G7: 3 | H7: Open | I7: SA, TC; TechLead | J7: ServiceNow instance request, MID server setup, network access. | K7: 4
A8: ECS-006 | B8: Access & credentials setup (admin, consultant, test accounts) | C8: ECS-001 | D8: Sprint 0 | E8: =WORKDAY('Project Plan'!$B$3,1) -> 45902 | F8: =WORKDAY(E8,1) -> 45903 | G8: 2 | H8: Open | I8: TC; TechLead | J8: ECS consultant accounts, customer admin accounts, SSO config baseline. | K8: 4
A9: ECS-007 | B9: Governance & decision rights workshop | C9: ECS-001 | D9: Sprint 0 | E9: =WORKDAY('Project Plan'!$B$3,2) -> 45903 | F9: =WORKDAY(E9,0) -> 45903 | G9: 1 | H9: Open | I9: EM, PC; Sponsor, CustPM | J9: Establish customization council, RACI, escalation path, decision log. | K9: 4
A10: ECS-008 | B10: Customization Council charter signed | C10: ECS-001 | D10: Sprint 0 | E10: =WORKDAY('Project Plan'!$B$3,3) -> 45904 | F10: =WORKDAY(E10,0) -> 45904 | G10: 1 | H10: Open | I10: EM; Sponsor | J10: Council charter defines quorum, meeting cadence, and veto rights for any scope deviation. | K10: 7
A11: ECS-009 | B11: Communication plan & cadence established | C11: ECS-001 | D11: Sprint 0 | E11: =WORKDAY('Project Plan'!$B$3,2) -> 45903 | F11: =WORKDAY(E11,0) -> 45903 | G11: 1 | H11: Open | I11: EM; CustPM | J11: Weekly status report schedule, bi-weekly sponsor sync, sprint demo invites. | K11: 4
A12: ECS-010 | B12: Risk register initialized | C12: ECS-001 | D12: Sprint 0 | E12: =WORKDAY('Project Plan'!$B$3,3) -> 45904 | F12: =WORKDAY(E12,0) -> 45904 | G12: 1 | H12: Open | I12: EM, PC; CustPM | J12: Populate with known risks: data readiness, SME availability, environment delays. | K12: 4
A13: ECS-011 | B13: Foundation Data Pack distributed to customer | C13: ECS-001 | D13: Sprint 0 | E13: =WORKDAY('Project Plan'!$B$3,4) -> 45905 | F13: =WORKDAY(E13,0) -> 45905 | G13: 1 | H13: Open | I13: PC; CustPM | J13: AP-01 workbooks: users, locations, departments, groups, assignment rules, SLAs, schedules. | K13: 4
A14: ECS-012 | B14: Stakeholder mapping completed | C14: ECS-001 | D14: Sprint 0 | E14: =WORKDAY('Project Plan'!$B$3,4) -> 45905 | F14: =WORKDAY(E14,0) -> 45905 | G14: 1 | H14: Open | I14: EM; CustPM | J14: Identify all SMEs, decision owners, and change champions per process area. | K14: 4
A15: ECS-013 | B15: Sprint 0 readiness validation (ECS checklist) | C15: ECS-001 | D15: Sprint 0 | E15: =WORKDAY('Project Plan'!$B$3,9) -> 45912 | F15: =WORKDAY(E15,0) -> 45912 | G15: 1 | H15: Open | I15: EM; CustPM | J15: Confirm: env provisioned, access live, governance signed, data pack distributed, risks logged. | K15: 5,6,7,8,9,10,11,12
A16: ECS-014 | B16: ✦ MILESTONE: Sprint 0 Complete — Ready to Build | C16: ECS-001 | D16: Sprint 0 | E16: =WORKDAY('Project Plan'!$B$3,9) -> 45912 | F16: =WORKDAY(E16,0) -> 45912 | G16: 0 | H16: Open | K16: 13
A17: ECS-015 | B17: SPRINT 1 — PLATFORM FOUNDATION & ITSM DESIGN | D17: Month 1 | E17: =WORKDAY('Project Plan'!$B$3,10) -> 45915 | F17: =WORKDAY(E17,9) -> 45926 | G17: 10 | H17: Open | I17: SA, PC; CustPM, TechLead | J17: Weeks 3–4. Platform stand-up, CSDM, and ITSM design workshops.
A18: ECS-016 | B18: Sprint 1 planning session | C18: ECS-015 | D18: Month 1 | E18: =WORKDAY('Project Plan'!$B$3,10) -> 45915 | F18: =WORKDAY(E18,0) -> 45915 | G18: 1 | H18: Open | I18: EM, SA; CustPM | J18: Story review, sprint backlog confirmation, acceptance criteria. | K18: 14
A19: ECS-017 | B19: Platform architecture stand-up & baseline configuration | C19: ECS-015 | D19: Month 1 | E19: =WORKDAY('Project Plan'!$B$3,10) -> 45915 | F19: =WORKDAY(E19,2) -> 45917 | G19: 3 | H19: Open | I19: SA, TC; TechLead | J19: CMDB scope settings, update sets, source control, MID server validation. | K19: 16,5
A20: ECS-018 | B20: CSDM definition workshop | C20: ECS-015 | D20: Month 1 | E20: =WORKDAY('Project Plan'!$B$3,10) -> 45915 | F20: =WORKDAY(E20,1) -> 45916 | G20: 2 | H20: Open | I20: SA, PC; CustPM, TechLead | J20: Map customer services, apps, and CIs to CSDM layers. Define service taxonomy. | K20: 16
A21: ECS-019 | B21: CSDM validation against ServiceNow data model | C21: ECS-015 | D21: Month 1 | E21: =WORKDAY('Project Plan'!$B$3,12) -> 45917 | F21: =WORKDAY(E21,1) -> 45918 | G21: 2 | H21: Open | I21: SA; TechLead | J21: Validate service-CI relationships; confirm Business Service and Technical Service scope. | K21: 18
A22: ECS-020 | B22: ITSM design workshop — Incident Management | C22: ECS-015 | D22: Month 1 | E22: =WORKDAY('Project Plan'!$B$3,10) -> 45915 | F22: =WORKDAY(E22,0) -> 45915 | G22: 1 | H22: Open | I22: PC; SME-ITSM | J22: State model, categorization, priority matrix, routing logic, SLA tiers. | K22: 16
A23: ECS-021 | B23: ITSM design workshop — Problem Management | C23: ECS-015 | D23: Month 1 | E23: =WORKDAY('Project Plan'!$B$3,11) -> 45916 | F23: =WORKDAY(E23,0) -> 45916 | G23: 1 | H23: Open | I23: PC; SME-ITSM | J23: Problem identification triggers, investigation workflow, known error base. | K23: 20
A24: ECS-022 | B24: ITSM design workshop — Request Management | C24: ECS-015 | D24: Month 1 | E24: =WORKDAY('Project Plan'!$B$3,12) -> 45917 | F24: =WORKDAY(E24,0) -> 45917 | G24: 1 | H24: Open | I24: PC; SME-ITSM | J24: Request types, fulfillment model, approval tiers, SLA targets. | K24: 21
A25: ECS-023 | B25: Foundation Data Pack review — users, groups, locations | C25: ECS-015 | D25: Month 1 | E25: =WORKDAY('Project Plan'!$B$3,13) -> 45918 | F25: =WORKDAY(E25,1) -> 45919 | G25: 2 | H25: Open | I25: PC; SME-ITSM | J25: Review customer-returned workbooks; identify gaps before Sprint 3 config. | K25: 11
A26: ECS-024 | B26: Assignment rules & SLA design review | C26: ECS-015 | D26: Month 1 | E26: =WORKDAY('Project Plan'!$B$3,14) -> 45919 | F26: =WORKDAY(E26,0) -> 45919 | G26: 1 | H26: Open | I26: PC; SME-ITSM | J26: Confirm assignment group structure, SLA definitions, and escalation schedules. | K26: 23
A27: ECS-025 | B27: Sprint 1 demo | C27: ECS-015 | D27: Month 1 | E27: =WORKDAY('Project Plan'!$B$3,18) -> 45925 | F27: =WORKDAY(E27,0) -> 45925 | G27: 1 | H27: Open | I27: SA, PC; Sponsor, CustPM | J27: Demo: platform baseline, CSDM service map, design decision recap. | K27: 17,19,24
A28: ECS-026 | B28: Sprint 1 retro | C28: ECS-015 | D28: Month 1 | E28: =WORKDAY('Project Plan'!$B$3,19) -> 45926 | F28: =WORKDAY(E28,0) -> 45926 | G28: 1 | H28: Open | I28: EM; CustPM | J28: Velocity, blockers, action items. Update risk register. | K28: 25
A29: ECS-027 | B29: ✦ MILESTONE: Sprint 1 Complete | C29: ECS-015 | D29: Month 1 | E29: =WORKDAY('Project Plan'!$B$3,19) -> 45926 | F29: =WORKDAY(E29,0) -> 45926 | G29: 0 | H29: Open | K29: 26
A30: ECS-028 | B30: SPRINT 2 — DISCOVERY & CMDB FOUNDATION | D30: Month 1 | E30: =WORKDAY('Project Plan'!$B$3,20) -> 45929 | F30: =WORKDAY(E30,9) -> 45940 | G30: 10 | H30: Open | I30: SA, TC; TechLead | J30: Weeks 5–6. Discovery tooling, Service Graph Connectors, CMDB normalization, catalog scope.
A31: ECS-029 | B31: Sprint 2 planning session | C31: ECS-028 | D31: Month 1 | E31: =WORKDAY('Project Plan'!$B$3,20) -> 45929 | F31: =WORKDAY(E31,0) -> 45929 | G31: 1 | H31: Open | I31: EM, SA; CustPM | K31: 27
A32: ECS-030 | B32: Discovery tool installation & network scan configuration | C32: ECS-028 | D32: Month 1 | E32: =WORKDAY('Project Plan'!$B$3,20) -> 45929 | F32: =WORKDAY(E32,2) -> 45931 | G32: 3 | H32: Open | I32: TC; TechLead | J32: Discovery schedules, credentials, network range scoping. | K32: 29
A33: ECS-031 | B33: Service Graph Connectors — SCCM / Intune porting | C33: ECS-028 | D33: Month 1 | E33: =WORKDAY('Project Plan'!$B$3,20) -> 45929 | F33: =WORKDAY(E33,3) -> 45932 | G33: 4 | H33: Open | I33: TC; TechLead | J33: Port connectors from prior system; validate CI population in CMDB. | K33: 29
A34: ECS-032 | B34: CMDB normalization — scope & approach workshop | C34: ECS-028 | D34: Month 1 | E34: =WORKDAY('Project Plan'!$B$3,20) -> 45929 | F34: =WORKDAY(E34,0) -> 45929 | G34: 1 | H34: Open | I34: SA, PC; TechLead | J34: Agree CI classes in scope, normalization rules, rogue CI cleanup approach. | K34: 29
A35: ECS-033 | B35: CI class selection workshop | C35: ECS-028 | D35: Month 1 | E35: =WORKDAY('Project Plan'!$B$3,21) -> 45930 | F35: =WORKDAY(E35,0) -> 45930 | G35: 1 | H35: Open | I35: SA; TechLead | J35: Select Server, Network, Application CI classes; confirm relationship types. | K35: 32,19
A36: ECS-034 | B36: Initial CMDB data load & relationship validation | C36: ECS-028 | D36: Month 1 | E36: =WORKDAY('Project Plan'!$B$3,22) -> 45931 | F36: =WORKDAY(E36,2) -> 45933 | G36: 3 | H36: Open | I36: TC; TechLead | J36: Load SCCM/Intune data; validate CI counts, duplicates, relationship integrity. | K36: 33
A37: ECS-035 | B37: Service catalog — category structure design workshop | C37: ECS-028 | D37: Month 1 | E37: =WORKDAY('Project Plan'!$B$3,20) -> 45929 | F37: =WORKDAY(E37,0) -> 45929 | G37: 1 | H37: Open | I37: PC; SME-Catalog | J37: Rationalize legacy categories; target ≤15 top-level categories OOTB. | K37: 29
A38: ECS-036 | B38: Service catalog — item inventory & prioritization | C38: ECS-028 | D38: Month 1 | E38: =WORKDAY('Project Plan'!$B$3,21) -> 45930 | F38: =WORKDAY(E38,1) -> 45931 | G38: 2 | H38: Open | I38: PC; SME-Catalog | J38: Inventory existing items; prioritize 13–15 for Sprint 4/6 build. | K38: 35
A39: ECS-037 | B39: Sprint 2 demo | C39: ECS-028 | D39: Month 1 | E39: =WORKDAY('Project Plan'!$B$3,28) -> 45939 | F39: =WORKDAY(E39,0) -> 45939 | G39: 1 | H39: Open | I39: SA, TC; Sponsor, CustPM | J39: Demo: Discovery scan, CMDB CIs, Service Graph connector results, catalog scope. | K39: 30,31,34,36
A40: ECS-038 | B40: Sprint 2 retro | C40: ECS-028 | D40: Month 1 | E40: =WORKDAY('Project Plan'!$B$3,29) -> 45940 | F40: =WORKDAY(E40,0) -> 45940 | G40: 1 | H40: Open | I40: EM; CustPM | K40: 37
...

Sheet Roles Reference
A1: ECS FEDERAL — ENGAGEMENT ROLES REFERENCE
A2: CODE | B2: ROLE TITLE | C2: TEAM | D2: RESPONSIBILITIES | E2: TYPICAL FTE COMMITMENT
A3: EM | B3: Engagement Manager | C3: ECS | D3: Overall engagement delivery, governance, escalation, sponsor relationship, risk management. | E3: 100% during engagement
A4: SA | B4: Solution Architect | C4: ECS | D4: Platform architecture, CSDM, technical decisions, accelerator pack design, integration oversight. | E4: 100% during engagement
A5: PC | B5: Process Consultant | C5: ECS | D5: Workshops facilitation, OOTB defense, discipline how-to guides, UAT support, training. | E5: 100% during engagement
A6: TC | B6: Technical Consultant | C6: ECS | D6: ServiceNow configuration, scripting (minimal), data loads, integration builds. | E6: 100% during engagement
A7: PM | B7: Practice Manager | C7: ECS | D7: Practice oversight, trust-but-verify reviews, escalation authority, lessons learned. | E7: 20% throughout
A8: Sponsor | B8: Project Sponsor | C8: Customer | D8: Executive decisions, budget authority, customization council, go-live authorization. | E8: 4–8 hrs/week
A9: CustPM | B9: Customer Project Manager | C9: Customer | D9: Day-to-day coordination, SME scheduling, status reporting to sponsor, action item tracking. | E9: 50–100% during engagement
A10: TechLead | B10: Customer Technical Lead | C10: Customer | D10: Environment access, integration credentials, CI/CD pipeline, technical approvals. | E10: 25–50% during engagement
A11: SME-ITSM | B11: ITSM Subject Matter Expert | C11: Customer | D11: Process decisions for Incident, Problem, Change, Request. Workshop participation. | E11: 50% during relevant sprints
A12: SME-Catalog | B12: Catalog SME | C12: Customer | D12: Catalog item content, category decisions, fulfillment workflow approvals. | E12: 50% during Sprints 2, 4, 6
A13: SME-HR | B13: HR / Employee Exp SME | C13: Customer | D13: Employee Center content, Virtual Agent topics, knowledge article content. | E13: 50% during Sprint 5
... A15: End-Users | B15: UAT Testers | C15: Customer | D15: Execute UAT test scenarios per process area. Log defects via ECS defect template. | E15: 100% during UAT (Weeks 15–16)
A18: RACI LEGEND
A19: R | B19: Responsible | C19: Does the work. Assigned as ECS Primary or Customer Primary.
A20: A | B20: Accountable | C20: Owns the outcome. One person per task.
A21: C | B21: Consulted | C21: Provides input. Assigned as ECS Support or Customer Support.
A22: I | B22: Informed | C22: Receives status updates. Tracked via Governance cadence.

Sheet Instructions
A1: HOW TO USE THIS PROJECT PLAN
A2: STEP | B2: INSTRUCTION | C2: WHERE
A3: 1. Set Start Date | B3: Go to the 'Project Plan' tab. In cell B3, enter your engagement start date (first Monday of Sprint 0). All 110 task dates recalculate automatically via WORKDAY formulas. | C3: Project Plan · B3
A4: 2. Tailor the Plan | B4: Adjust task names, durations, and dependencies to match your specific engagement scope. Add customer-specific tasks in the appropriate sprint section. Do not change column order — the MS Project import depends on it. | C4: Project Plan
A5: 3. Import to MS Project | B5: Go to the 'MS Project Import' tab. Save that sheet as CSV (UTF-8). Open MS Project > File > Import > CSV. Map: Name→Name, Duration→Duration, Start→Start, Finish→Finish, Predecessors→Predecessors, Resource Names→Resource Names. Select 'Create a new project'. Set working calendar to match your engagement. | C5: MS Project Import tab
A6: 4. Import to ServiceNow PPM | B6: Go to the 'SNow PPM Import' tab. Copy the data range (headers + rows). In ServiceNow: Modules > Project > Projects > [your project] > Task Import. Paste or upload the CSV. Map fields: short_description, planned_start_date, planned_end_date, assigned_to_role, description. The task_number field becomes the display number in SNow. | C6: SNow PPM Import tab
A7: 5. Track Status | B7: Update the 'Status' column (col N) and '% Complete' column (col O) on the Project Plan tab throughout the engagement. Status values: Not Started / In Progress / Complete / Blocked. | C7: Project Plan · cols N, O
A8: 6. Governance | B8: Rows 108–110 are recurring governance tasks (weekly status, bi-weekly sponsor sync, customization council). These are not in the MS Project/SNow import sheets — add them manually as recurring tasks in your project tool. | C8: Project Plan · rows 108–110
A9: 7. Dependency Logic | B9: The Predecessors column lists task IDs (column A). A comma-separated list means 'finish-to-start' for all listed tasks. When a predecessor task date shifts, update the start_day offset in the source data and re-run, or adjust dates manually in MS Project/SNow after import. | C9: Project Plan · col I
A10: 8. Roles | B10: See the 'Roles Reference' tab for full role definitions and RACI legend. ECS Primary = Responsible (does the work). Customer Primary = Accountable or key Consulted. Update role codes to match named individuals when running a live engagement. | C10: Roles Reference tab
